<?xml version="1.0" encoding="UTF-8"?>
<testng-results skipped="0" failed="4" ignored="0" total="6" passed="2">
  <reporter-output>
  </reporter-output>
  <suite name="Ethoca_Challenge" duration-ms="76908" started-at="2019-01-05T21:10:04Z" finished-at="2019-01-05T21:11:21Z">
    <groups>
    </groups>
    <test name="MagicMouse_Purchase" duration-ms="28551" started-at="2019-01-05T21:10:04Z" finished-at="2019-01-05T21:10:33Z">
      <class name="exercise.Test01">
        <test-method status="PASS" signature="iniTest()[pri:0, instance:exercise.Test01@7a3d45bd]" name="iniTest" is-config="true" duration-ms="3052" started-at="2019-01-05T21:10:04Z" finished-at="2019-01-05T21:10:07Z">
          <reporter-output>
          </reporter-output>
        </test-method> <!-- iniTest -->
        <test-method status="FAIL" signature="TestCase01()[pri:0, instance:exercise.Test01@7a3d45bd]" name="TestCase01" duration-ms="24763" started-at="2019-01-05T21:10:07Z" finished-at="2019-01-05T21:10:32Z">
          <exception class="java.lang.AssertionError">
            <message>
              <![CDATA[Error has occured during Validating product]]>
            </message>
            <full-stacktrace>
              <![CDATA[java.lang.AssertionError: Error has occured during Validating product
at org.testng.Assert.fail(Assert.java:96)
at businessComponents.BusinessComponents.validateProductSelect(BusinessComponents.java:90)
at exercise.Test01.TestCase01(Test01.java:27)
at sun.reflect.NativeMethodAccessorImpl.invoke0(Native Method)
at sun.reflect.NativeMethodAccessorImpl.invoke(Unknown Source)
at sun.reflect.DelegatingMethodAccessorImpl.invoke(Unknown Source)
at java.lang.reflect.Method.invoke(Unknown Source)
at org.testng.internal.MethodInvocationHelper.invokeMethod(MethodInvocationHelper.java:124)
at org.testng.internal.Invoker.invokeMethod(Invoker.java:580)
at org.testng.internal.Invoker.invokeTestMethod(Invoker.java:716)
at org.testng.internal.Invoker.invokeTestMethods(Invoker.java:988)
at org.testng.internal.TestMethodWorker.invokeTestMethods(TestMethodWorker.java:125)
at org.testng.internal.TestMethodWorker.run(TestMethodWorker.java:109)
at org.testng.TestRunner.privateRun(TestRunner.java:648)
at org.testng.TestRunner.run(TestRunner.java:505)
at org.testng.SuiteRunner.runTest(SuiteRunner.java:455)
at org.testng.SuiteRunner.runSequentially(SuiteRunner.java:450)
at org.testng.SuiteRunner.privateRun(SuiteRunner.java:415)
at org.testng.SuiteRunner.run(SuiteRunner.java:364)
at org.testng.SuiteRunnerWorker.runSuite(SuiteRunnerWorker.java:52)
at org.testng.SuiteRunnerWorker.run(SuiteRunnerWorker.java:84)
at org.testng.TestNG.runSuitesSequentially(TestNG.java:1208)
at org.testng.TestNG.runSuitesLocally(TestNG.java:1137)
at org.testng.TestNG.runSuites(TestNG.java:1049)
at org.testng.TestNG.run(TestNG.java:1017)
at org.testng.remote.AbstractRemoteTestNG.run(AbstractRemoteTestNG.java:114)
at org.testng.remote.RemoteTestNG.initAndRun(RemoteTestNG.java:251)
at org.testng.remote.RemoteTestNG.main(RemoteTestNG.java:77)
]]>
            </full-stacktrace>
          </exception> <!-- java.lang.AssertionError -->
          <reporter-output>
          </reporter-output>
        </test-method> <!-- TestCase01 -->
        <test-method status="PASS" signature="cleanUp()[pri:0, instance:exercise.Test01@7a3d45bd]" name="cleanUp" is-config="true" duration-ms="677" started-at="2019-01-05T21:10:32Z" finished-at="2019-01-05T21:10:33Z">
          <reporter-output>
          </reporter-output>
        </test-method> <!-- cleanUp -->
      </class> <!-- exercise.Test01 -->
    </test> <!-- MagicMouse_Purchase -->
    <test name="AppleTV_Purchase" duration-ms="48287" started-at="2019-01-05T21:10:33Z" finished-at="2019-01-05T21:11:21Z">
      <class name="exercise.Test02">
        <test-method status="PASS" signature="iniTest()[pri:0, instance:exercise.Test02@64f6106c]" name="iniTest" is-config="true" duration-ms="2157" started-at="2019-01-05T21:10:33Z" finished-at="2019-01-05T21:10:35Z">
          <reporter-output>
          </reporter-output>
        </test-method> <!-- iniTest -->
        <test-method status="PASS" signature="login()[pri:1, instance:exercise.Test02@64f6106c]" name="login" duration-ms="2331" started-at="2019-01-05T21:10:35Z" finished-at="2019-01-05T21:10:37Z">
          <reporter-output>
          </reporter-output>
        </test-method> <!-- login -->
        <test-method status="PASS" signature="SelectItem()[pri:2, instance:exercise.Test02@64f6106c]" name="SelectItem" duration-ms="2847" started-at="2019-01-05T21:10:37Z" finished-at="2019-01-05T21:10:40Z">
          <reporter-output>
          </reporter-output>
        </test-method> <!-- SelectItem -->
        <test-method status="FAIL" signature="validateProduct_Select()[pri:3, instance:exercise.Test02@64f6106c]" name="validateProduct_Select" duration-ms="20081" started-at="2019-01-05T21:10:40Z" finished-at="2019-01-05T21:11:00Z">
          <exception class="java.lang.AssertionError">
            <message>
              <![CDATA[Error has occured during Validating product]]>
            </message>
            <full-stacktrace>
              <![CDATA[java.lang.AssertionError: Error has occured during Validating product
at org.testng.Assert.fail(Assert.java:96)
at businessComponents.BusinessComponents.validateProductSelect(BusinessComponents.java:90)
at exercise.Test02.validateProduct_Select(Test02.java:35)
at sun.reflect.NativeMethodAccessorImpl.invoke0(Native Method)
at sun.reflect.NativeMethodAccessorImpl.invoke(Unknown Source)
at sun.reflect.DelegatingMethodAccessorImpl.invoke(Unknown Source)
at java.lang.reflect.Method.invoke(Unknown Source)
at org.testng.internal.MethodInvocationHelper.invokeMethod(MethodInvocationHelper.java:124)
at org.testng.internal.Invoker.invokeMethod(Invoker.java:580)
at org.testng.internal.Invoker.invokeTestMethod(Invoker.java:716)
at org.testng.internal.Invoker.invokeTestMethods(Invoker.java:988)
at org.testng.internal.TestMethodWorker.invokeTestMethods(TestMethodWorker.java:125)
at org.testng.internal.TestMethodWorker.run(TestMethodWorker.java:109)
at org.testng.TestRunner.privateRun(TestRunner.java:648)
at org.testng.TestRunner.run(TestRunner.java:505)
at org.testng.SuiteRunner.runTest(SuiteRunner.java:455)
at org.testng.SuiteRunner.runSequentially(SuiteRunner.java:450)
at org.testng.SuiteRunner.privateRun(SuiteRunner.java:415)
at org.testng.SuiteRunner.run(SuiteRunner.java:364)
at org.testng.SuiteRunnerWorker.runSuite(SuiteRunnerWorker.java:52)
at org.testng.SuiteRunnerWorker.run(SuiteRunnerWorker.java:84)
at org.testng.TestNG.runSuitesSequentially(TestNG.java:1208)
at org.testng.TestNG.runSuitesLocally(TestNG.java:1137)
at org.testng.TestNG.runSuites(TestNG.java:1049)
at org.testng.TestNG.run(TestNG.java:1017)
at org.testng.remote.AbstractRemoteTestNG.run(AbstractRemoteTestNG.java:114)
at org.testng.remote.RemoteTestNG.initAndRun(RemoteTestNG.java:251)
at org.testng.remote.RemoteTestNG.main(RemoteTestNG.java:77)
]]>
            </full-stacktrace>
          </exception> <!-- java.lang.AssertionError -->
          <reporter-output>
          </reporter-output>
        </test-method> <!-- validateProduct_Select -->
        <test-method status="FAIL" signature="enterUserDetails()[pri:4, instance:exercise.Test02@64f6106c]" name="enterUserDetails" duration-ms="20030" started-at="2019-01-05T21:11:00Z" finished-at="2019-01-05T21:11:20Z">
          <exception class="java.lang.AssertionError">
            <message>
              <![CDATA[Error has occured during User entry details page]]>
            </message>
            <full-stacktrace>
              <![CDATA[java.lang.AssertionError: Error has occured during User entry details page
at org.testng.Assert.fail(Assert.java:96)
at businessComponents.BusinessComponents.enterUserDetails(BusinessComponents.java:106)
at exercise.Test02.enterUserDetails(Test02.java:40)
at sun.reflect.NativeMethodAccessorImpl.invoke0(Native Method)
at sun.reflect.NativeMethodAccessorImpl.invoke(Unknown Source)
at sun.reflect.DelegatingMethodAccessorImpl.invoke(Unknown Source)
at java.lang.reflect.Method.invoke(Unknown Source)
at org.testng.internal.MethodInvocationHelper.invokeMethod(MethodInvocationHelper.java:124)
at org.testng.internal.Invoker.invokeMethod(Invoker.java:580)
at org.testng.internal.Invoker.invokeTestMethod(Invoker.java:716)
at org.testng.internal.Invoker.invokeTestMethods(Invoker.java:988)
at org.testng.internal.TestMethodWorker.invokeTestMethods(TestMethodWorker.java:125)
at org.testng.internal.TestMethodWorker.run(TestMethodWorker.java:109)
at org.testng.TestRunner.privateRun(TestRunner.java:648)
at org.testng.TestRunner.run(TestRunner.java:505)
at org.testng.SuiteRunner.runTest(SuiteRunner.java:455)
at org.testng.SuiteRunner.runSequentially(SuiteRunner.java:450)
at org.testng.SuiteRunner.privateRun(SuiteRunner.java:415)
at org.testng.SuiteRunner.run(SuiteRunner.java:364)
at org.testng.SuiteRunnerWorker.runSuite(SuiteRunnerWorker.java:52)
at org.testng.SuiteRunnerWorker.run(SuiteRunnerWorker.java:84)
at org.testng.TestNG.runSuitesSequentially(TestNG.java:1208)
at org.testng.TestNG.runSuitesLocally(TestNG.java:1137)
at org.testng.TestNG.runSuites(TestNG.java:1049)
at org.testng.TestNG.run(TestNG.java:1017)
at org.testng.remote.AbstractRemoteTestNG.run(AbstractRemoteTestNG.java:114)
at org.testng.remote.RemoteTestNG.initAndRun(RemoteTestNG.java:251)
at org.testng.remote.RemoteTestNG.main(RemoteTestNG.java:77)
]]>
            </full-stacktrace>
          </exception> <!-- java.lang.AssertionError -->
          <reporter-output>
          </reporter-output>
        </test-method> <!-- enterUserDetails -->
        <test-method status="FAIL" signature="validateTranPage()[pri:5, instance:exercise.Test02@64f6106c]" name="validateTranPage" duration-ms="102" started-at="2019-01-05T21:11:20Z" finished-at="2019-01-05T21:11:20Z">
          <exception class="java.lang.AssertionError">
            <message>
              <![CDATA[Transaction page NOT displayed expected [true] but found [false]]]>
            </message>
            <full-stacktrace>
              <![CDATA[java.lang.AssertionError: Transaction page NOT displayed expected [true] but found [false]
at org.testng.Assert.fail(Assert.java:96)
at org.testng.Assert.failNotEquals(Assert.java:776)
at org.testng.Assert.assertTrue(Assert.java:44)
at businessComponents.BusinessComponents.validateTranPage(BusinessComponents.java:117)
at exercise.Test02.validateTranPage(Test02.java:45)
at sun.reflect.NativeMethodAccessorImpl.invoke0(Native Method)
at sun.reflect.NativeMethodAccessorImpl.invoke(Unknown Source)
at sun.reflect.DelegatingMethodAccessorImpl.invoke(Unknown Source)
at java.lang.reflect.Method.invoke(Unknown Source)
at org.testng.internal.MethodInvocationHelper.invokeMethod(MethodInvocationHelper.java:124)
at org.testng.internal.Invoker.invokeMethod(Invoker.java:580)
at org.testng.internal.Invoker.invokeTestMethod(Invoker.java:716)
at org.testng.internal.Invoker.invokeTestMethods(Invoker.java:988)
at org.testng.internal.TestMethodWorker.invokeTestMethods(TestMethodWorker.java:125)
at org.testng.internal.TestMethodWorker.run(TestMethodWorker.java:109)
at org.testng.TestRunner.privateRun(TestRunner.java:648)
at org.testng.TestRunner.run(TestRunner.java:505)
at org.testng.SuiteRunner.runTest(SuiteRunner.java:455)
at org.testng.SuiteRunner.runSequentially(SuiteRunner.java:450)
at org.testng.SuiteRunner.privateRun(SuiteRunner.java:415)
at org.testng.SuiteRunner.run(SuiteRunner.java:364)
at org.testng.SuiteRunnerWorker.runSuite(SuiteRunnerWorker.java:52)
at org.testng.SuiteRunnerWorker.run(SuiteRunnerWorker.java:84)
at org.testng.TestNG.runSuitesSequentially(TestNG.java:1208)
at org.testng.TestNG.runSuitesLocally(TestNG.java:1137)
at org.testng.TestNG.runSuites(TestNG.java:1049)
at org.testng.TestNG.run(TestNG.java:1017)
at org.testng.remote.AbstractRemoteTestNG.run(AbstractRemoteTestNG.java:114)
at org.testng.remote.RemoteTestNG.initAndRun(RemoteTestNG.java:251)
at org.testng.remote.RemoteTestNG.main(RemoteTestNG.java:77)
]]>
            </full-stacktrace>
          </exception> <!-- java.lang.AssertionError -->
          <reporter-output>
          </reporter-output>
        </test-method> <!-- validateTranPage -->
        <test-method status="PASS" signature="cleanUp()[pri:0, instance:exercise.Test02@64f6106c]" name="cleanUp" is-config="true" duration-ms="702" started-at="2019-01-05T21:11:20Z" finished-at="2019-01-05T21:11:21Z">
          <reporter-output>
          </reporter-output>
        </test-method> <!-- cleanUp -->
      </class> <!-- exercise.Test02 -->
    </test> <!-- AppleTV_Purchase -->
  </suite> <!-- Ethoca_Challenge -->
</testng-results>
